Workbook

Sheet LEEME
A1: Plantilla base · Dinámica RI, equivalencias y salones
A2: Llena las hojas en este archivo y después se integran al simulador HTML. Los nombres de hojas y columnas deben conservarse.
A4: Hoja | B4: Para qué sirve | C4: Obligatoria
A5: base_ni_ri_2030_2040 | B5: Trayectoria base editable de NI, RI y MT por año, periodo, campus, nivel y modalidad. | C5: Sí
A6: equivalencias_promedio | B6: Promedio histórico de alumnos que cuentan como NI, pero entran académicamente a S2, S3, S4, etc. | C6: Sí
A7: tasas_avance | B7: Tasas por campus y nivel para mover alumnos entre semestres: S1→S2, S8→Egreso, S8→Rezago, etc. | C7: Sí
A8: presencialidad_semestre | B8: % de presencialidad o uso de salones por semestre académico. | C8: Sí
A9: distribucion_ri_semestre | B9: Distribución opcional de RI total entre semestres. Si no existe, se puede estimar con las tasas. | C9: Opcional
A10: catalogos | B10: Listas auxiliares para validación: periodos, niveles, modalidades y estados. | C10: No editar si no es necesario
A13: Concepto | B13: Definición
A14: NI total | B14: Alumno que cuenta como nuevo ingreso para captación. Puede entrar a S1 o por equivalencia a un semestre posterior.
A15: RI total | B15: Alumno de reingreso reportado en la base. En el cálculo interno se distribuye por semestre.
A16: Equivalencias | B16: No se suman adicional a la MT. Solo reubican parte de los NI al semestre académico correcto.
A17: Rezago | B17: Alumno que llegó al último semestre, pero no egresó en el corte y se mantiene activo por materias/trámites pendientes.
A18: MT | B18: Matrícula total = NI total + RI total.
A19: DEFAULT | B19: Si una tasa o configuración aplica para todos los campus, puedes usar campus = DEFAULT. Una fila específica por campus debe tener prioridad en el simulador.

Sheet catalogos
A1: Catálogos para validación
A2: Puedes agregar campus o modalidades si lo necesitas. No cambies los nombres principales de nivel/periodo/estado.
A4: campus | C4: nivel | E4: modalidad | G4: periodo | I4: semestres_prepa | K4: semestres_profesional | M4: estados_destino | O4: metodo_equivalencia | Q4: usa_salon
A5: DEFAULT | C5: Preparatoria | E5: Presencial | G5: AD | I5: S1 | K5: S1 | M5: S1 | O5: fijo | Q5: 1
A6: Institucional | C6: Profesional | E6: Híbrido | G6: EM | I6: S2 | K6: S2 | M6: S2 | O6: pct_sobre_ni | Q6: 0
A7: Aguascalientes | I7: S3 | K7: S3 | M7: S3
A8: Cancún | I8: S4 | K8: S4 | M8: S4
A9: Chihuahua | I9: S5 | K9: S5 | M9: S5
A10: Ciudad Juárez | I10: S6 | K10: S6 | M10: S6
A11: Cuautitlán Izcalli | I11: Rezago | K11: S7 | M11: S7
A12: Cuernavaca | K12: S8 | M12: S8
A13: Culiacán | K13: Rezago | M13: Rezago
A14: Cumbres | M14: Egreso
A15: Durango | M15: Baja
A16: Ferrería
A17: Guadalajara
A18: Guadalupe
A19: Hermosillo
A20: Laguna
A21: Las Torres
A22: Los Mochis
A23: Mazatlán
A24: Mérida
A25: Nuevo Laredo
A26: Obregón
A27: Puebla
... A38: Morelia

Sheet base_ni_ri_2030_2040
A1: Base NI / RI / MT 2030–2040
A2: Carga aquí la trayectoria base anual o por periodo. Esta base no es meta: es el punto de partida editable del simulador.
A4: anio | B4: periodo | C4: campus | D4: nivel | E4: modalidad | F4: ni_total | G4: ri_total | H4: mt_total | I4: validacion_mt | J4: comentario
A5: 2030 | B5: AD | C5: Aguascalientes | D5: Preparatoria | E5: Presencial | F5: 244.65 | G5: 426 | H5: =tbl_base_ni_ri[[#This Row],[ni_total]]+tbl_base_ni_ri[[#This Row],[ri_total]] -> 670.65 | I5: =IF(OR(F5="",G5="",H5=""),"",IF(ABS(H5-F5-G5)<0.01,"OK","Revisar MT")) -> OK | J5: Ejemplo: sustituir con dato base
A6: 2031 | B6: AD | C6: Aguascalientes | D6: Preparatoria | E6: Presencial | F6: 256.8825 | G6: 441 | H6: =tbl_base_ni_ri[[#This Row],[ni_total]]+tbl_base_ni_ri[[#This Row],[ri_total]] -> 697.8825 | I6: =IF(OR(F6="",G6="",H6=""),"",IF(ABS(H6-F6-G6)<0.01,"OK","Revisar MT")) -> OK | J6: Ejemplo: sustituir con dato base
A7: 2032 | B7: AD | C7: Aguascalientes | D7: Preparatoria | E7: Presencial | F7: 269.72663 | G7: 456 | H7: =tbl_base_ni_ri[[#This Row],[ni_total]]+tbl_base_ni_ri[[#This Row],[ri_total]] -> 725.72663 | I7: =IF(OR(F7="",G7="",H7=""),"",IF(ABS(H7-F7-G7)<0.01,"OK","Revisar MT")) -> OK | J7: Ejemplo: sustituir con dato base
A8: 2033 | B8: AD | C8: Aguascalientes | D8: Preparatoria | E8: Presencial | F8: 283.21296 | G8: 479 | H8: =tbl_base_ni_ri[[#This Row],[ni_total]]+tbl_base_ni_ri[[#This Row],[ri_total]] -> 762.21296 | I8: =IF(OR(F8="",G8="",H8=""),"",IF(ABS(H8-F8-G8)<0.01,"OK","Revisar MT")) -> OK | J8: Ejemplo: sustituir con dato base
A9: 2034 | B9: AD | C9: Aguascalientes | D9: Preparatoria | E9: Presencial | F9: 291.70934 | G9: 506 | H9: =tbl_base_ni_ri[[#This Row],[ni_total]]+tbl_base_ni_ri[[#This Row],[ri_total]] -> 797.70934 | I9: =IF(OR(F9="",G9="",H9=""),"",IF(ABS(H9-F9-G9)<0.01,"OK","Revisar MT")) -> OK | J9: Ejemplo: sustituir con dato base
A10: 2035 | B10: AD | C10: Aguascalientes | D10: Preparatoria | E10: Presencial | F10: 300.46063 | G10: 536 | H10: =tbl_base_ni_ri[[#This Row],[ni_total]]+tbl_base_ni_ri[[#This Row],[ri_total]] -> 836.46063 | I10: =IF(OR(F10="",G10="",H10=""),"",IF(ABS(H10-F10-G10)<0.01,"OK","Revisar MT")) -> OK | J10: Ejemplo: sustituir con dato base
A11: 2036 | B11: AD | C11: Aguascalientes | D11: Preparatoria | E11: Presencial | F11: 309.47444 | G11: 572 | H11: =tbl_base_ni_ri[[#This Row],[ni_total]]+tbl_base_ni_ri[[#This Row],[ri_total]] -> 881.47444 | I11: =IF(OR(F11="",G11="",H11=""),"",IF(ABS(H11-F11-G11)<0.01,"OK","Revisar MT")) -> OK | J11: Ejemplo: sustituir con dato base
A12: 2037 | B12: AD | C12: Aguascalientes | D12: Preparatoria | E12: Presencial | F12: 319.06815 | G12: 594 | H12: =tbl_base_ni_ri[[#This Row],[ni_total]]+tbl_base_ni_ri[[#This Row],[ri_total]] -> 913.06815 | I12: =IF(OR(F12="",G12="",H12=""),"",IF(ABS(H12-F12-G12)<0.01,"OK","Revisar MT")) -> OK | J12: Ejemplo: sustituir con dato base
A13: 2038 | B13: AD | C13: Aguascalientes | D13: Preparatoria | E13: Presencial | F13: 328.95926 | G13: 618 | H13: =tbl_base_ni_ri[[#This Row],[ni_total]]+tbl_base_ni_ri[[#This Row],[ri_total]] -> 946.95926 | I13: =IF(OR(F13="",G13="",H13=""),"",IF(ABS(H13-F13-G13)<0.01,"OK","Revisar MT")) -> OK | J13: Ejemplo: sustituir con dato base
A14: 2039 | B14: AD | C14: Aguascalientes | D14: Preparatoria | E14: Presencial | F14: 339.157 | G14: 642 | H14: =tbl_base_ni_ri[[#This Row],[ni_total]]+tbl_base_ni_ri[[#This Row],[ri_total]] -> 981.157 | I14: =IF(OR(F14="",G14="",H14=""),"",IF(ABS(H14-F14-G14)<0.01,"OK","Revisar MT")) -> OK | J14: Ejemplo: sustituir con dato base
A15: 2040 | B15: AD | C15: Aguascalientes | D15: Preparatoria | E15: Presencial | F15: 349.67087 | G15: 667 | H15: =tbl_base_ni_ri[[#This Row],[ni_total]]+tbl_base_ni_ri[[#This Row],[ri_total]] -> 1016.6709 | I15: =IF(OR(F15="",G15="",H15=""),"",IF(ABS(H15-F15-G15)<0.01,"OK","Revisar MT")) -> OK | J15: Ejemplo: sustituir con dato base
A16: 2030 | B16: AD | C16: Cancún | D16: Preparatoria | E16: Presencial | F16: 344.41 | G16: 531 | H16: =tbl_base_ni_ri[[#This Row],[ni_total]]+tbl_base_ni_ri[[#This Row],[ri_total]] -> 875.41 | I16: =IF(OR(F16="",G16="",H16=""),"",IF(ABS(H16-F16-G16)<0.01,"OK","Revisar MT")) -> OK | J16: Ejemplo: sustituir con dato base
... A26: 2040 | B26: AD | C26: Cancún | D26: Preparatoria | E26: Presencial | F26: 380.44291 | G26: 612 | H26: =tbl_base_ni_ri[[#This Row],[ni_total]]+tbl_base_ni_ri[[#This Row],[ri_total]] -> 992.44291 | I26: =IF(OR(F26="",G26="",H26=""),"",IF(ABS(H26-F26-G26)<0.01,"OK","Revisar MT")) -> OK | J26: Ejemplo: sustituir con dato base
A27: 2030 | B27: AD | C27: Chihuahua | D27: Preparatoria | E27: Presencial | F27: 249.26 | G27: 300 | H27: =tbl_base_ni_ri[[#This Row],[ni_total]]+tbl_base_ni_ri[[#This Row],[ri_total]] -> 549.26 | I27: =IF(OR(F27="",G27="",H27=""),"",IF(ABS(H27-F27-G27)<0.01,"OK","Revisar MT")) -> OK
A28: 2031 | B28: AD | C28: Chihuahua | D28: Preparatoria | E28: Presencial | F28: 256.7378 | G28: 307 | H28: =tbl_base_ni_ri[[#This Row],[ni_total]]+tbl_base_ni_ri[[#This Row],[ri_total]] -> 563.7378 | I28: =IF(OR(F28="",G28="",H28=""),"",IF(ABS(H28-F28-G28)<0.01,"OK","Revisar MT")) -> OK
A29: 2032 | B29: AD | C29: Chihuahua | D29: Preparatoria | E29: Presencial | F29: 264.43993 | G29: 312 | H29: =tbl_base_ni_ri[[#This Row],[ni_total]]+tbl_base_ni_ri[[#This Row],[ri_total]] -> 576.43993 | I29: =IF(OR(F29="",G29="",H29=""),"",IF(ABS(H29-F29-G29)<0.01,"OK","Revisar MT")) -> OK
A30: 2033 | B30: AD | C30: Chihuahua | D30: Preparatoria | E30: Presencial | F30: 272.37313 | G30: 323 | H30: =tbl_base_ni_ri[[#This Row],[ni_total]]+tbl_base_ni_ri[[#This Row],[ri_total]] -> 595.37313 | I30: =IF(OR(F30="",G30="",H30=""),"",IF(ABS(H30-F30-G30)<0.01,"OK","Revisar MT")) -> OK
A31: 2034 | B31: AD | C31: Chihuahua | D31: Preparatoria | E31: Presencial | F31: 277.82059 | G31: 345 | H31: =tbl_base_ni_ri[[#This Row],[ni_total]]+tbl_base_ni_ri[[#This Row],[ri_total]] -> 622.82059 | I31: =IF(OR(F31="",G31="",H31=""),"",IF(ABS(H31-F31-G31)<0.01,"OK","Revisar MT")) -> OK
A32: 2035 | B32: AD | C32: Chihuahua | D32: Preparatoria | E32: Presencial | F32: 283.37701 | G32: 376 | H32: =tbl_base_ni_ri[[#This Row],[ni_total]]+tbl_base_ni_ri[[#This Row],[ri_total]] -> 659.37701 | I32: =IF(OR(F32="",G32="",H32=""),"",IF(ABS(H32-F32-G32)<0.01,"OK","Revisar MT")) -> OK
A33: 2036 | B33: AD | C33: Chihuahua | D33: Preparatoria | E33: Presencial | F33: 289.04455 | G33: 396 | H33: =tbl_base_ni_ri[[#This Row],[ni_total]]+tbl_base_ni_ri[[#This Row],[ri_total]] -> 685.04455 | I33: =IF(OR(F33="",G33="",H33=""),"",IF(ABS(H33-F33-G33)<0.01,"OK","Revisar MT")) -> OK
A34: 2037 | B34: AD | C34: Chihuahua | D34: Preparatoria | E34: Presencial | F34: 291.64595 | G34: 412 | H34: =tbl_base_ni_ri[[#This Row],[ni_total]]+tbl_base_ni_ri[[#This Row],[ri_total]] -> 703.64595 | I34: =IF(OR(F34="",G34="",H34=""),"",IF(ABS(H34-F34-G34)<0.01,"OK","Revisar MT")) -> OK
A35: 2038 | B35: AD | C35: Chihuahua | D35: Preparatoria | E35: Presencial | F35: 294.27076 | G35: 443 | H35: =tbl_base_ni_ri[[#This Row],[ni_total]]+tbl_base_ni_ri[[#This Row],[ri_total]] -> 737.27076 | I35: =IF(OR(F35="",G35="",H35=""),"",IF(ABS(H35-F35-G35)<0.01,"OK","Revisar MT")) -> OK
A36: 2039 | B36: AD | C36: Chihuahua | D36: Preparatoria | E36: Presencial | F36: 296.9192 | G36: 476 | H36: =tbl_base_ni_ri[[#This Row],[ni_total]]+tbl_base_ni_ri[[#This Row],[ri_total]] -> 772.9192 | I36: =IF(OR(F36="",G36="",H36=""),"",IF(ABS(H36-F36-G36)<0.01,"OK","Revisar MT")) -> OK
A37: 2040 | B37: AD | C37: Chihuahua | D37: Preparatoria | E37: Presencial | F37: 299.59147 | G37: 500 | H37: =tbl_base_ni_ri[[#This Row],[ni_total]]+tbl_base_ni_ri[[#This Row],[ri_total]] -> 799.59147 | I37: =IF(OR(F37="",G37="",H37=""),"",IF(ABS(H37-F37-G37)<0.01,"OK","Revisar MT")) -> OK
A38: 2030 | B38: AD | C38: Ciudad Juárez | D38: Preparatoria | E38: Presencial | F38: 342.023 | G38: 605 | H38: =tbl_base_ni_ri[[#This Row],[ni_total]]+tbl_base_ni_ri[[#This Row],[ri_total]] -> 947.023 | I38: =IF(OR(F38="",G38="",H38=""),"",IF(ABS(H38-F38-G38)<0.01,"OK","Revisar MT")) -> OK
... A697: 2040 | B697: AD | C697: Morelia | D697: Profesional | E697: Presencial | F697: 300 | G697: 553 | H697: =tbl_base_ni_ri[[#This Row],[ni_total]]+tbl_base_ni_ri[[#This Row],[ri_total]] -> 853 | I697: =IF(OR(F697="",G697="",H697=""),"",IF(ABS(H697-F697-G697)<0.01,"OK","Revisar MT")) -> OK
A698: 2030 | C698: Institucional | D698: Posgrado | F698: 4876 | G698: 12494 | H698: =tbl_base_ni_ri[[#This Row],[ni_total]]+tbl_base_ni_ri[[#This Row],[ri_total]] -> 17370 | I698: =IF(OR(F698="",G698="",H698=""),"",IF(ABS(H698-F698-G698)<0.01,"OK","Revisar MT")) -> OK
A699: 2031 | C699: Institucional | D699: Posgrado | F699: 4892 | G699: 12535 | H699: =tbl_base_ni_ri[[#This Row],[ni_total]]+tbl_base_ni_ri[[#This Row],[ri_total]] -> 17427 | I699: =IF(OR(F699="",G699="",H699=""),"",IF(ABS(H699-F699-G699)<0.01,"OK","Revisar MT")) -> OK
A700: 2032 | C700: Institucional | D700: Posgrado | F700: 5013 | G700: 12300 | H700: =tbl_base_ni_ri[[#This Row],[ni_total]]+tbl_base_ni_ri[[#This Row],[ri_total]] -> 17313 | I700: =IF(OR(F700="",G700="",H700=""),"",IF(ABS(H700-F700-G700)<0.01,"OK","Revisar MT")) -> OK
A701: 2033 | C701: Institucional | D701: Posgrado | F701: 5196 | G701: 12200 | H701: =tbl_base_ni_ri[[#This Row],[ni_total]]+tbl_base_ni_ri[[#This Row],[ri_total]] -> 17396 | I701: =IF(OR(F701="",G701="",H701=""),"",IF(ABS(H701-F701-G701)<0.01,"OK","Revisar MT")) -> OK
A702: 2034 | C702: Institucional | D702: Posgrado | F702: 5482 | G702: 12150 | H702: =tbl_base_ni_ri[[#This Row],[ni_total]]+tbl_base_ni_ri[[#This Row],[ri_total]] -> 17632 | I702: =IF(OR(F702="",G702="",H702=""),"",IF(ABS(H702-F702-G702)<0.01,"OK","Revisar MT")) -> OK
A703: 2035 | C703: Institucional | D703: Posgrado | F703: 5885 | G703: 12100 | H703: =tbl_base_ni_ri[[#This Row],[ni_total]]+tbl_base_ni_ri[[#This Row],[ri_total]] -> 17985 | I703: =IF(OR(F703="",G703="",H703=""),"",IF(ABS(H703-F703-G703)<0.01,"OK","Revisar MT")) -> OK
A704: 2036 | C704: Institucional | D704: Posgrado | F704: 6465 | G704: 12100 | H704: =tbl_base_ni_ri[[#This Row],[ni_total]]+tbl_base_ni_ri[[#This Row],[ri_total]] -> 18565 | I704: =IF(OR(F704="",G704="",H704=""),"",IF(ABS(H704-F704-G704)<0.01,"OK","Revisar MT")) -> OK
A705: 2037 | C705: Institucional | D705: Posgrado | F705: 7215 | G705: 12100 | H705: =tbl_base_ni_ri[[#This Row],[ni_total]]+tbl_base_ni_ri[[#This Row],[ri_total]] -> 19315 | I705: =IF(OR(F705="",G705="",H705=""),"",IF(ABS(H705-F705-G705)<0.01,"OK","Revisar MT")) -> OK
A706: 2038 | C706: Institucional | D706: Posgrado | F706: 8105 | G706: 12350 | H706: =tbl_base_ni_ri[[#This Row],[ni_total]]+tbl_base_ni_ri[[#This Row],[ri_total]] -> 20455 | I706: =IF(OR(F706="",G706="",H706=""),"",IF(ABS(H706-F706-G706)<0.01,"OK","Revisar MT")) -> OK
A707: 2039 | C707: Institucional | D707: Posgrado | F707: 9165 | G707: 12800 | H707: =tbl_base_ni_ri[[#This Row],[ni_total]]+tbl_base_ni_ri[[#This Row],[ri_total]] -> 21965 | I707: =IF(OR(F707="",G707="",H707=""),"",IF(ABS(H707-F707-G707)<0.01,"OK","Revisar MT")) -> OK
A708: 2040 | C708: Institucional | D708: Posgrado | F708: 10273 | G708: 13400 | H708: =tbl_base_ni_ri[[#This Row],[ni_total]]+tbl_base_ni_ri[[#This Row],[ri_total]] -> 23673 | I708: =IF(OR(F708="",G708="",H708=""),"",IF(ABS(H708-F708-G708)<0.01,"OK","Revisar MT")) -> OK
...

Sheet equivalencias_promedio
A1: Equivalencias promedio histórico
A2: Alumnos que cuentan como NI, pero académicamente ingresan a un semestre distinto a S1. No se suman adicional a MT; solo reubican NI.
A4: campus | B4: nivel | C4: modalidad | D4: periodo | E4: semestre_ingreso | F4: equivalencias_promedio | G4: pct_sobre_ni | H4: metodo | I4: comentario
A5: DEFAULT | B5: Preparatoria | C5: Presencial | D5: AD | E5: S2 | F5: 0 | H5: fijo | I5: Ejemplo, cambia a promedio histórico
A6: DEFAULT | B6: Preparatoria | C6: Presencial | D6: AD | E6: S3 | F6: 0 | H6: fijo | I6: Ejemplo, cambia a promedio histórico
A7: DEFAULT | B7: Profesional | C7: Presencial | D7: AD | E7: S3 | F7: 0 | H7: fijo | I7: Ejemplo, cambia a promedio histórico
A8: DEFAULT | B8: Profesional | C8: Presencial | D8: AD | E8: S5 | F8: 0 | H8: fijo | I8: Ejemplo, cambia a promedio histórico
A9: Cancún | B9: Profesional | C9: Presencial | D9: AD | E9: S3 | G9: 0.05 | H9: pct_sobre_ni | I9: Ejemplo con porcentaje sobre NI

Sheet tasas_avance
A1: Tasas de avance / permanencia por campus
A2: Usa campus DEFAULT para tasa general. Si un campus tiene una tasa distinta, agrega una fila específica del campus.
A4: campus | B4: nivel | C4: modalidad | D4: periodo_origen | E4: estado_origen | F4: estado_destino | G4: tasa | H4: comentario
A5: DEFAULT | B5: Preparatoria | C5: Presencial | D5: AD | E5: S1 | F5: S2 | G5: 0.925
A6: DEFAULT | B6: Preparatoria | C6: Presencial | D6: AD | E6: S2 | F6: S3 | G6: 0.903
A7: DEFAULT | B7: Preparatoria | C7: Presencial | D7: AD | E7: S3 | F7: S4 | G7: 0.963
A8: DEFAULT | B8: Preparatoria | C8: Presencial | D8: AD | E8: S4 | F8: S5 | G8: 0.911
A9: DEFAULT | B9: Preparatoria | C9: Presencial | D9: AD | E9: S5 | F9: S6 | G9: 0.976
A10: DEFAULT | B10: Preparatoria | C10: Presencial | D10: AD | E10: S6 | F10: Egreso | G10: 0.981
A11: DEFAULT | B11: Preparatoria | C11: Presencial | D11: AD | E11: S6 | F11: Rezago | G11: 0.019
A12: DEFAULT | B12: Preparatoria | C12: Presencial | D12: AD | E12: Rezago | F12: Egreso | G12: 0.8 | H12: Ajustar con histórico
A13: DEFAULT | B13: Preparatoria | C13: Presencial | D13: AD | E13: Rezago | F13: Rezago | G13: 0.2 | H13: Ajustar con histórico
A14: DEFAULT | B14: Profesional | C14: Presencial | D14: AD | E14: S1 | F14: S2 | G14: 0.895
A15: DEFAULT | B15: Profesional | C15: Presencial | D15: AD | E15: S2 | F15: S3 | G15: 0.928
A16: DEFAULT | B16: Profesional | C16: Presencial | D16: AD | E16: S3 | F16: S4 | G16: 0.958
A17: DEFAULT | B17: Profesional | C17: Presencial | D17: AD | E17: S4 | F17: S5 | G17: 0.968
A18: DEFAULT | B18: Profesional | C18: Presencial | D18: AD | E18: S5 | F18: S6 | G18: 0.975
A19: DEFAULT | B19: Profesional | C19: Presencial | D19: AD | E19: S6 | F19: S7 | G19: 0.977
A20: DEFAULT | B20: Profesional | C20: Presencial | D20: AD | E20: S7 | F20: S8 | G20: 0.979
A21: DEFAULT | B21: Profesional | C21: Presencial | D21: AD | E21: S8 | F21: Egreso | G21: 0.71
A22: DEFAULT | B22: Profesional | C22: Presencial | D22: AD | E22: S8 | F22: Rezago | G22: 0.29
A23: DEFAULT | B23: Profesional | C23: Presencial | D23: AD | E23: Rezago | F23: Egreso | G23: 0.4 | H23: Ajustar con histórico
A24: DEFAULT | B24: Profesional | C24: Presencial | D24: AD | E24: Rezago | F24: Rezago | G24: 0.6 | H24: Ajustar con histórico

Sheet presencialidad_semestre
A1: % presencialidad por semestre
A2: Esta sería la parte editable del simulador para decidir qué semestres usan salones y con qué intensidad.
A4: campus | B4: nivel | C4: modalidad | D4: semestre | E4: pct_presencialidad | F4: usa_salon | G4: comentario
A5: DEFAULT | B5: Preparatoria | C5: Presencial | D5: S1 | E5: 1 | F5: 1
A6: DEFAULT | B6: Preparatoria | C6: Presencial | D6: S2 | E6: 1 | F6: 1
A7: DEFAULT | B7: Preparatoria | C7: Presencial | D7: S3 | E7: 1 | F7: 1
A8: DEFAULT | B8: Preparatoria | C8: Presencial | D8: S4 | E8: 1 | F8: 1
A9: DEFAULT | B9: Preparatoria | C9: Presencial | D9: S5 | E9: 1 | F9: 1
A10: DEFAULT | B10: Preparatoria | C10: Presencial | D10: S6 | E10: 1 | F10: 1
A11: DEFAULT | B11: Preparatoria | C11: Presencial | D11: Rezago | E11: 0.2 | F11: 1
A12: DEFAULT | B12: Profesional | C12: Presencial | D12: S1 | E12: 1 | F12: 1
A13: DEFAULT | B13: Profesional | C13: Presencial | D13: S2 | E13: 1 | F13: 1
A14: DEFAULT | B14: Profesional | C14: Presencial | D14: S3 | E14: 1 | F14: 1
A15: DEFAULT | B15: Profesional | C15: Presencial | D15: S4 | E15: 1 | F15: 1
A16: DEFAULT | B16: Profesional | C16: Presencial | D16: S5 | E16: 0.7 | F16: 1
... A20: DEFAULT | B20: Profesional | C20: Presencial | D20: Rezago | E20: 0.2 | F20: 1

Sheet distribucion_ri_semestre
A1: Distribución de RI por semestre
A2: Hoja opcional. Sirve para repartir el RI total base entre semestres antes de calcular salones. Los porcentajes por campus/nivel/periodo deben sumar 100%.
A4: campus | B4: nivel | C4: modalidad | D4: periodo | E4: semestre | F4: pct_ri | G4: comentario
A5: Cancún | B5: Profesional | C5: Presencial | D5: AD | E5: S1 | F5: 0.24224806 | G5: Ejemplo, ajustar con histórico
A6: Cancún | B6: Profesional | C6: Presencial | D6: AD | E6: S2 | F6: 0 | G6: Ejemplo, ajustar con histórico
A7: Cancún | B7: Profesional | C7: Presencial | D7: AD | E7: S3 | F7: 0.22093023 | G7: Ejemplo, ajustar con histórico
A8: Cancún | B8: Profesional | C8: Presencial | D8: AD | E8: S4 | F8: 0.011627907 | G8: Ejemplo, ajustar con histórico
A9: Cancún | B9: Profesional | C9: Presencial | D9: AD | E9: S5 | F9: 0.25193798 | G9: Ejemplo, ajustar con histórico
A10: Cancún | B10: Profesional | C10: Presencial | D10: AD | E10: S6 | F10: 0.01744186 | G10: Ejemplo, ajustar con histórico
A11: Cancún | B11: Profesional | C11: Presencial | D11: AD | E11: S7 | F11: 0.16666667 | G11: Ejemplo, ajustar con histórico
A12: Cancún | B12: Profesional | C12: Presencial | D12: AD | E12: S8 | F12: 0.089147287 | G12: Ejemplo, ajustar con histórico
A13: Chihuahua | B13: Profesional | C13: Presencial | D13: AD | E13: S1 | F13: 0.27131783 | G13: Ejemplo, ajustar con histórico
A14: Chihuahua | B14: Profesional | C14: Presencial | D14: AD | E14: S2 | F14: 0 | G14: Ejemplo, ajustar con histórico
A15: Chihuahua | B15: Profesional | C15: Presencial | D15: AD | E15: S3 | F15: 0.23643411 | G15: Ejemplo, ajustar con histórico
A16: Chihuahua | B16: Profesional | C16: Presencial | D16: AD | E16: S4 | F16: 0.01744186 | G16: Ejemplo, ajustar con histórico
... A18: Chihuahua | B18: Profesional | C18: Presencial | D18: AD | E18: S6 | F18: 0.01744186 | G18: Ejemplo, ajustar con histórico
A19: Chihuahua | B19: Profesional | C19: Presencial | D19: AD | E19: S7 | F19: 0.26356589
A20: Chihuahua | B20: Profesional | C20: Presencial | D20: AD | E20: S8 | F20: 0.075581395
A21: Ciudad Juárez | B21: Profesional | C21: Presencial | D21: AD | E21: S1 | F21: 0.23643411
A22: Ciudad Juárez | B22: Profesional | C22: Presencial | D22: AD | E22: S2 | F22: 0.0019379845
A23: Ciudad Juárez | B23: Profesional | C23: Presencial | D23: AD | E23: S3 | F23: 0.22674419
A24: Ciudad Juárez | B24: Profesional | C24: Presencial | D24: AD | E24: S4 | F24: 0.031007752
A25: Ciudad Juárez | B25: Profesional | C25: Presencial | D25: AD | E25: S5 | F25: 0.19573643
A26: Ciudad Juárez | B26: Profesional | C26: Presencial | D26: AD | E26: S6 | F26: 0.040697674
A27: Ciudad Juárez | B27: Profesional | C27: Presencial | D27: AD | E27: S7 | F27: 0.15310078
A28: Ciudad Juárez | B28: Profesional | C28: Presencial | D28: AD | E28: S8 | F28: 0.073643411
A29: Cuautitlán Izcalli | B29: Profesional | C29: Presencial | D29: AD | E29: S1 | F29: 0.55813953
A30: Cuautitlán Izcalli | B30: Profesional | C30: Presencial | D30: AD | E30: S2 | F30: 0.0019379845
... A244: Zapopan | B244: Profesional | C244: Presencial | D244: AD | E244: S8 | F244: 0.046511628

Sheet validaciones
A1: Validaciones rápidas
A2: Estas fórmulas ayudan a revisar si algunas hojas tienen inconsistencias básicas.
A4: Validación | B4: Resultado esperado | C4: Qué revisar
A5: MT = NI + RI en base_ni_ri_2030_2040 | B5: validacion_mt debe decir OK | C5: Si aparece Revisar MT, corrige mt_total o deja que sea NI + RI.
A6: Distribución RI por semestre | B6: pct_ri debe sumar 100% por campus/nivel/periodo | C6: Revisar manualmente o con tabla dinámica si cargas muchos campus.
A7: Tasas desde un mismo estado | B7: Suma de destinos por origen debería ser <= 100% | C7: Ejemplo: S8→Egreso + S8→Rezago.
A8: Equivalencias promedio | B8: No deben ser mayores al NI total del periodo | C8: Si usas fijo y el NI proyectado baja, revisar el promedio.

Sheet parametros_multicampus
A1: Módulo multicampus / flex / presencial | E1: Nota v43
A2: La clasificación se hace por grupo académico estimado. En S6-S7 primero divide por la cantidad de rutas de enfoque de la hoja rutas_por_programa. | E2: Ruta redondeada | F2: Ejemplo: 21 alumnos / 6 rutas = 4 por ruta.
A3: parametro | B3: valor | C3: descripcion | E3: Clasificación | F3: Con 4 alumnos cae como Multicampus, no Mixto.
A4: min_multicampus | B4: 4 | C4: Menor a este valor se clasifica como Flex. | E4: Presenciales | F4: Se reportan total, mañana y tarde según configuración de Salones.
A5: max_multicampus | B5: 11 | C5: De min_multicampus a este valor se clasifica como Multicampus. | E5: Parámetros sugeridos | F5: ruta_semestre_min=6, ruta_semestre_max=7
A6: capacidad_salon_flex | B6: 4 | C6: Capacidad en alumnos del espacio/salón flex.
A7: capacidad_salon_multicampus | B7: 12 | C7: Capacidad en alumnos del espacio/salón multicampus. | E7: Nota v44
A8: capacidad_salon_normal | B8: 25 | C8: Capacidad en alumnos del salón presencial normal. | E8: Salones presenciales | F8: Se calculan agregando alumnos y dividiendo entre 25.
A9: semestre_min | B9: 1 | C9: Primer semestre a revisar. | E9: Antes | F9: Se sumaban salones por grupo y eso podía inflar mañana/tarde.
A10: semestre_max | B10: 8 | C10: Último semestre a revisar. | E10: Comparación | F10: Pres. mañana debe ser comparable con la lógica de Salones.
A11: ruta_semestre_min | B11: 6 | C11: Desde este semestre se divide entre rutas de enfoque.
A12: ruta_semestre_max | B12: 7 | C12: Hasta este semestre se divide entre rutas de enfoque. | E12: Nota v45
A13: umbral_salones_normales | B13: 10 | C13: Salones presenciales mínimos para sugerir bloque/edificio. | E13: S1 | F13: Se reparte desde NI Profesional del año.
E14: S2-S8 | F14: Se reparten desde RI Profesional usando la distribución de semestre normalizada.
E15: Validación | F15: La pestaña Multicampus muestra NI S1 y RI S2-S8 para verificar cuadratura.
E16: Ejemplo | F16: Si Campus dice NI Prof 2030 = 191, S1 debe sumar aprox. 191.
E18: Nota v46
E19: Base 2030-2040 | F19: El HTML respeta exactamente NI, RI y MT de la hoja base.
E20: S1 | F20: Se reparte con NI Profesional.
E21: S2-S8 | F21: Se reparte con RI Profesional y debe cuadrar al total RI.
E22: S8 | F22: Cuenta como RI en validación, pero NO genera Flex/Multicampus/Presencial.
E23: Evaluación de espacios | F23: Solo S1-S7.
E24: % programa | F24: Se normaliza a 100% para repartir todos los NI/RI entre los programas cargados.
E26: Nota v47
E27: S8 | F27: Ya no aparece en el desglose por programa ni genera espacios.
E28: Tabla de programas | F28: Ya no muestra etiquetas NI/RI dentro de las celdas.
E29: Cuadre Salones | F29: Pres. mañana en Multicampus usa el mismo cálculo de la pestaña Salones.
E30: Carrera nueva | F30: Se puede simular desde el HTML. Se suma a NI, RI y MT de Profesional.
E31: RI carrera nueva | F31: Se estima con el RI/NI del campus en cada año.
E32: Rutas carrera nueva | F32: Se capturan en el simulador para S6 y S7.
E33: Prioridad | F33: Los espacios multicampus/flex son complemento; salones presenciales mañana cuadra con Salones.
E35: Nota v48
E36: Tasas 2030-2040 | F36: Vuelven a mostrarse. Si no se editan, se respeta la base del Excel.
E37: Si se editan | F37: Recalcula desde el año previo usando la tasa capturada.
E38: Validación removida | F38: Se quitó la tabla de validación de Multicampus.
E39: RI S2-S8 | F39: El reparto base se fuerza a cuadrar con RI Profesional.
E40: S8 | F40: No aparece en desglose de programas ni genera espacios.
E41: Salones | F41: Profesional en Salones y Multicampus excluye S8 y usa el mismo total.
E42: Por semestre | F42: Los salones mañana/tarde se asignan por peso para que sumen exactamente el total anual.
E44: Nota v49
...

Sheet Maps bimestral
A1: Base de troncalidad por programa y certificado
A3: Programa | B3: Certificado | C3: Tipo de certificado | D3: Secuencia | E3: Numero de Semestre | F3: Observaciones
A4: Licenciatura en Administración de Empresas | B4: Transformación digital | C4: Troncal | D4: 1 | E4: 1 | F4: Reemplazar ejemplos por datos reales. La llave principal será Programa + Certificado + Numero de Semestre.
A5: Licenciatura en Administración de Empresas | B5: Fundamentos de programación | D5: 3 | E5: 1
A6: Licenciatura en Administración de Empresas | B6: Estrategia y ventaja competitiva | D6: 2 | E6: 1
A7: Licenciatura en Administración de Empresas | B7: Certificado de Lengua Extranjera 1 | D7: 4 | E7: 1
A8: Licenciatura en Administración de Empresas | B8: Emprendimiento | D8: 6 | E8: 2
A9: Licenciatura en Administración de Empresas | B9: Big Data Analytics | D9: 7 | E9: 2
A10: Licenciatura en Administración de Empresas | B10: Administración de operaciones | D10: 5 | E10: 2
A11: Licenciatura en Administración de Empresas | B11: Certificado de Lengua Extranjera 2 | D11: 8 | E11: 2
A12: Licenciatura en Administración de Empresas | B12: Mercadotecnia estratégica | D12: 9 | E12: 3
A13: Licenciatura en Administración de Empresas | B13: Derecho corporativo | D13: 11 | E13: 3
A14: Licenciatura en Administración de Empresas | B14: Administración del talento humano | D14: 10 | E14: 3
A15: Licenciatura en Administración de Empresas | B15: Certificado de Lengua Extranjera 3 | D15: 12 | E15: 3
A16: Licenciatura en Administración de Empresas | B16: Mercadotecnia digital | D16: 15 | E16: 4
... A339: Licenciatura en Mercadotecnia | B339: Certificado de Lengua Extranjera 7 | D339: 28 | E339: 7

Sheet Portafolio Actual
A1: Portafolio actual de programas por campus
A3: Campus | B3: Nivel | C3: Programa | D3: Modalidad | E3: Activo | F3: Observaciones
A4: Cancún | B4: Profesional | C4: Licenciatura en Diseño Gráfico y Animación | D4: Presencial | E4: SI | F4: Capturar un renglón por campus-programa activo.
A5: Cancún | B5: Profesional | C5: Licenciatura en Derecho | D5: Presencial | E5: SI
A6: Cancún | B6: Profesional | C6: Licenciatura en Ingeniería en Desarrollo de Software | D6: Presencial | E6: SI
A7: Cancún | B7: Profesional | C7: Licenciatura en Mercadotecnia | D7: Presencial | E7: SI
A8: Cancún | B8: Profesional | C8: Licenciatura en Administración de Empresas | D8: Presencial | E8: SI
A9: Cancún | B9: Profesional | C9: Licenciatura en Comercio y Negocios Internacionales | D9: Presencial | E9: SI
A10: Cancún | B10: Profesional | C10: Licenciatura en Nutrición | D10: Presencial | E10: SI
A11: Chihuahua | B11: Profesional | C11: Licenciatura en Diseño Gráfico y Animación | D11: Presencial | E11: SI
A12: Chihuahua | B12: Profesional | C12: Licenciatura en Derecho | D12: Presencial | E12: SI
A13: Chihuahua | B13: Profesional | C13: Licenciatura en Ingeniería en Desarrollo de Software | D13: Presencial | E13: SI
A14: Chihuahua | B14: Profesional | C14: Licenciatura en Mercadotecnia | D14: Presencial | E14: SI
A15: Chihuahua | B15: Profesional | C15: Licenciatura en Creación y Desarrollo de Empresas | D15: Presencial | E15: SI
A16: Chihuahua | B16: Profesional | C16: Licenciatura en Comercio y Negocios Internacionales | D16: Presencial | E16: SI
... A232: Zacatecas | B232: Profesional | C232: Licenciatura en Ingeniería Industrial | D232: Presencial | E232: SI

Sheet Rutas enfoque
A1: Rutas enfoque y reutilización de certificados | H1: Nota v42
H2: La división S6-S7 usa primero rutas_por_programa. | I2: Esta hoja queda como respaldo/detalle de certificados.
A3: Programa | B3: Ruta | C3: Certificado | D3: Numero de certificado | E3: Reutilizacion de certificados | F3: Observaciones | H3: Si rutas_por_programa dice 4 rutas: | I3: se divide entre 4 aunque aquí no estén todas las rutas detalladas.
A4: Licenciatura en Mercadotecnia | B4: Estrategia Publicitaria | C4: Diseño de productos | D4: Optativa 1 | E4: 1 | F4: Reutilización = número de rutas/programas donde se repite el certificado. | H4: Troncalidad: | I4: Maps bimestral sigue ayudando a agrupar certificados compartidos.
A5: Licenciatura en Mercadotecnia | B5: Estrategia Publicitaria | C5: UX/UI | D5: Optativa 5 | E5: 1
A6: Licenciatura en Mercadotecnia | B6: Estrategia Publicitaria | C6: Sociología del consumo | D6: Optativa 3 | E6: 1
A7: Licenciatura en Mercadotecnia | B7: Estrategia Publicitaria | C7: Publicidad | D7: Optativa 2 | E7: 1
A8: Licenciatura en Mercadotecnia | B8: Estrategia Publicitaria | C8: Diseño para medios digitales | D8: Optativa 6 | E8: 1
A9: Licenciatura en Mercadotecnia | B9: Estrategia Publicitaria | C9: Comercio detallista | D9: Optativa 4 | E9: 1
A10: Licenciatura en Mercadotecnia | B10: Estrategías de Mercadotecnia en Buscadores y Comercio Electrónico | C10: Analítica digital | D10: Optativa 6 | E10: 2
A11: Licenciatura en Mercadotecnia | B11: Estrategías de Mercadotecnia en Buscadores y Comercio Electrónico | C11: Serch engine optimization (SEO) | D11: Optativa 1 | E11: 1
A12: Licenciatura en Mercadotecnia | B12: Estrategías de Mercadotecnia en Buscadores y Comercio Electrónico | C12: Serch engine marketin (SEM) | D12: Optativa 2 | E12: 1
A13: Licenciatura en Mercadotecnia | B13: Estrategías de Mercadotecnia en Buscadores y Comercio Electrónico | C13: Marketing automation | D13: Optativa 3 | E13: 1
A14: Licenciatura en Mercadotecnia | B14: Estrategías de Mercadotecnia en Buscadores y Comercio Electrónico | C14: Growth hacking | D14: Optativa 4 | E14: 1
A15: Licenciatura en Mercadotecnia | B15: Estrategías de Mercadotecnia en Buscadores y Comercio Electrónico | C15: Comercio electrónico | D15: Optativa 5 | E15: 1
A16: Licenciatura en Mercadotecnia | B16: Gestión de ventas estratégicas | C16: Servicios y experiencia al cliente | D16: Optativa 5 | E16: 3
... A272: Licenciatura en Administración de Empresas | B272: Turismo | C272: Gestión de alimentos y Bebidas | D272: Optativa 3 | E272: 1

Sheet aportacion_ni_programa
A1: Aportación de NI por programa para repartir MT Profesional | J1: Nota v40
J2: Con solo 2026 basta. | K2: El simulador usa NI_programa / NI_total_campus por programa.
A3: Campus | B3: Periodo | C3: Nivel | D3: Programa | E3: Anio | F3: NI_programa | G3: NI_total_campus | H3: pct_aportacion | I3: Observaciones | J3: Si llenas pct_aportacion, se usa directo. | K3: Si no, divide NI_programa entre NI_total_campus.
A4: Cancún | B4: AD | C4: Profesional | D4: Licenciatura en Administración de Empresas | E4: 2026 | F4: 13 | G4: 105 | I4: Puedes llenar NI_programa y NI_total_campus o directamente pct_aportacion. | J4: Evita duplicar programa-campus-año. | K4: Si se duplica, puede inflar la mezcla porcentual.
A5: Cancún | B5: AD | C5: Profesional | D5: Licenciatura en Comercio y Negocios Internacionales | E5: 2026 | F5: 21 | G5: 105
A6: Cancún | B6: AD | C6: Profesional | D6: Licenciatura en Derecho | E6: 2026 | F6: 7 | G6: 105
A7: Cancún | B7: AD | C7: Profesional | D7: Licenciatura en Diseño Gráfico y Animación | E7: 2026 | F7: 10 | G7: 105
A8: Cancún | B8: AD | C8: Profesional | D8: Licenciatura en Ingeniería en Desarrollo de Software | E8: 2026 | F8: 26 | G8: 105
A9: Cancún | B9: AD | C9: Profesional | D9: Licenciatura en Mercadotecnia | E9: 2026 | F9: 13 | G9: 105
A10: Cancún | B10: AD | C10: Profesional | D10: Licenciatura en Nutrición | E10: 2026 | F10: 15 | G10: 105
A11: Chihuahua | B11: AD | C11: Profesional | D11: Licenciatura en Comercio y Negocios Internacionales | E11: 2026 | F11: 23 | G11: 107
A12: Chihuahua | B12: AD | C12: Profesional | D12: Licenciatura en Creación y Desarrollo de Empresas | E12: 2026 | F12: 12 | G12: 107
A13: Chihuahua | B13: AD | C13: Profesional | D13: Licenciatura en Derecho | E13: 2026 | F13: 14 | G13: 107
A14: Chihuahua | B14: AD | C14: Profesional | D14: Licenciatura en Diseño Gráfico y Animación | E14: 2026 | F14: 17 | G14: 107
A15: Chihuahua | B15: AD | C15: Profesional | D15: Licenciatura en Ingeniería Industrial | E15: 2026 | F15: 11 | G15: 107
A16: Chihuahua | B16: AD | C16: Profesional | D16: Licenciatura en Ingeniería Mecatrónica | E16: 2026 | F16: 11 | G16: 107
A17: Chihuahua | B17: AD | C17: Profesional | D17: Licenciatura en Ingeniería en Desarrollo de Software | E17: 2026 | F17: 19 | G17: 107
A18: Chihuahua | B18: AD | C18: Profesional | D18: Licenciatura en Mercadotecnia | E18: 2026 | F18: 0 | G18: 107 | H18: 0.001
A19: Ciudad Juárez | B19: AD | C19: Profesional | D19: Licenciatura en Comercio y Negocios Internacionales | E19: 2026 | F19: 33 | G19: 84
A20: Ciudad Juárez | B20: AD | C20: Profesional | D20: Licenciatura en Diseño Gráfico y Animación | E20: 2026 | F20: 4 | G20: 84
A21: Ciudad Juárez | B21: AD | C21: Profesional | D21: Licenciatura en Administración de Empresas | E21: 2026 | F21: 9 | G21: 84
A22: Ciudad Juárez | B22: AD | C22: Profesional | D22: Licenciatura en Ingeniería Industrial | E22: 2026 | F22: 9 | G22: 84
A23: Ciudad Juárez | B23: AD | C23: Profesional | D23: Licenciatura en Ingeniería Mecatrónica | E23: 2026 | F23: 13 | G23: 84
A24: Ciudad Juárez | B24: AD | C24: Profesional | D24: Licenciatura en Ingeniería en Desarrollo de Software | E24: 2026 | F24: 10 | G24: 84
A25: Ciudad Juárez | B25: AD | C25: Profesional | D25: Licenciatura en Mercadotecnia | E25: 2026 | F25: 6 | G25: 84
A26: Cuautitlán Izcalli | B26: AD | C26: Profesional | D26: Licenciatura en Administración de Empresas | E26: 2026 | F26: 21 | G26: 269
A27: Cuautitlán Izcalli | B27: AD | C27: Profesional | D27: Licenciatura en Comercio y Negocios Internacionales | E27: 2026 | F27: 42 | G27: 269
A28: Cuautitlán Izcalli | B28: AD | C28: Profesional | D28: Licenciatura en Contabilidad y Estrategia Financiera | E28: 2026 | F28: 20 | G28: 269
A29: Cuautitlán Izcalli | B29: AD | C29: Profesional | D29: Licenciatura en Derecho | E29: 2026 | F29: 20 | G29: 269
A30: Cuautitlán Izcalli | B30: AD | C30: Profesional | D30: Licenciatura en Diseño Gráfico y Animación | E30: 2026 | F30: 31 | G30: 269
... A37: Cuernavaca | B37: AD | C37: Profesional | D37: Licenciatura en Diseño Gráfico y Animación | E37: 2026 | F37: 10 | G37: 95
A38: Cuernavaca | B38: AD | C38: Profesional | D38: Licenciatura en Ingeniería Industrial | E38: 2026 | F38: 0 | G38: 95 | H38: 0.001
A39: Cuernavaca | B39: AD | C39: Profesional | D39: Licenciatura en Ingeniería Mecatrónica | E39: 2026 | F39: 19 | G39: 95
A40: Cuernavaca | B40: AD | C40: Profesional | D40: Licenciatura en Ingeniería en Desarrollo de Software | E40: 2026 | F40: 22 | G40: 95
A41: Cuernavaca | B41: AD | C41: Profesional | D41: Licenciatura en Mercadotecnia | E41: 2026 | F41: 14 | G41: 95
A42: Culiacán | B42: AD | C42: Profesional | D42: Licenciatura en Administración de Empresas | E42: 2026 | F42: 30 | G42: 250
A43: Culiacán | B43: AD | C43: Profesional | D43: Licenciatura en Comercio y Negocios Internacionales | E43: 2026 | F43: 62 | G43: 250
A44: Culiacán | B44: AD | C44: Profesional | D44: Licenciatura en Contabilidad y Estrategia Financiera | E44: 2026 | F44: 38 | G44: 250
A45: Culiacán | B45: AD | C45: Profesional | D45: Licenciatura en Diseño Gráfico y Animación | E45: 2026 | F45: 10 | G45: 250
A46: Culiacán | B46: AD | C46: Profesional | D46: Licenciatura en Ingeniería Industrial | E46: 2026 | F46: 39 | G46: 250
...

Sheet rutas_por_programa
A1: Cantidad de rutas de enfoque por programa | H1: Nota v43
A2: Llena esta hoja. Se usa para dividir los alumnos de S6 y S7 entre rutas de enfoque. | H2: S6-S7 se divide entre esta cantidad de rutas. | I2: Se usa redondeo hacia arriba: 21/6 = 4.
A3: Programa | B3: Cantidad de rutas de enfoque | C3: Notas | H3: Clasificación: | I3: <4 Flex | 4 a 11 Multicampus | 12+ Presencial
A4: Licenciatura en Ingeniería Mecatrónica | B4: 8 | C4: Borra o reemplaza este ejemplo | H4: Presenciales: | I4: Se desglosan en mañana/tarde con la configuración de Salones.
A5: Licenciatura en Ingeniería en Logística y Cadena de Suministro | B5: 3 | C5: Borra o reemplaza este ejemplo
A6: Licenciatura en Ingeniería en Desarrollo de Software | B6: 6
A7: Licenciatura en Ingeniería Industrial | B7: 4
A8: Licenciatura en Administración de Empresas | B8: 4
A9: Licenciatura en Comercio y Negocios Internacionales | B9: 2
A10: Licenciatura en Contabilidad y Estrategia Financiera | B10: 2
A11: Licenciatura en Creación y Desarrollo de Empresas | B11: 2
A12: Licenciatura en Derecho | B12: 4
A13: Licenciatura en Diseño Gráfico y Animación | B13: 3
A14: Licenciatura en Gastronomía Internacional | B14: 3
A15: Licenciatura en Mercadotecnia | B15: 4
A16: Ingeniero en Tecnología y trasnformación Digital | B16: 5
A17: Licenciatura en Administración y Desarrollo de talento | B17: 2
A18: Licenciatura en Educación | B18: 3

Sheet carreras_nuevas_2027
A1: Carreras nuevas 2027 por campus
A2: Llena una fila por campus-carrera nueva. Estas carreras empiezan en 2027: no aparecen en 2026. El NI propuesto se captura en la columna NI 2027; el simulador lo usa para repartir el NI total del campus en Multicampus, no para sumarlo doble a la pestaña Campus.
A3: Campus | B3: Periodo | C3: Nivel | D3: Programa | E3: Modalidad | F3: Activo | G3: Año inicio | H3: NI 2027 | I3: Cantidad de rutas de enfoque | J3: Observaciones
A4: Cd. Juarez | B4: AD | C4: Profesional | D4: Licenciatura en Contabilidad y Estrategia Financiera | E4: Presencial | F4: SI | G4: 2027 | H4: 25 | I4: 4 | J4: Borra esta fila y captura las carreras reales.
A5: Cumbres | B5: AD | C5: Profesional | D5: Licenciatura en Derecho | E5: Presencial | F5: SI | G5: 2027 | H5: 25 | I5: 3 | J5: La columna NI 2027 es la aportación esperada del programa.
A6: Tampico | B6: AD | C6: Profesional | D6: Licenciatura en Ingeniería en Desarrollo de Software | E6: Presencial | F6: SI | G6: 2027 | H6: 18
A7: Durango | B7: AD | C7: Profesional | D7: Licenciatura en Contabilidad y Estrategia Financiera | E7: Presencial | F7: SI | G7: 2027 | H7: 12
A8: Guadalupe | B8: AD | C8: Profesional | D8: Licenciatura en Contabilidad y Estrategia Financiera | E8: Presencial | F8: SI | G8: 2027 | H8: 12
A9: Hermosillo | B9: AD | C9: Profesional | D9: Licenciatura en Contabilidad y Estrategia Financiera | E9: Presencial | F9: SI | G9: 2027 | H9: 12
A10: Laguna | B10: AD | C10: Profesional | D10: Licenciatura en Contabilidad y Estrategia Financiera | E10: Presencial | F10: SI | G10: 2027 | H10: 18
A11: Nuevo Laredo | B11: AD | C11: Profesional | D11: Licenciatura en Ingeniería en Logística y Cadena de Suministro | E11: Presencial | F11: SI | G11: 2027 | H11: 18
A12: San Nicolás | B12: AD | C12: Profesional | D12: Licenciatura en Contabilidad y Estrategia Financiera | E12: Presencial | F12: SI | G12: 2027 | H12: 12
A13: Guadalajara | B13: AD | C13: Profesional | D13: Licenciatura en Creación y Desarrollo de Empresas | E13: Presencial | F13: SI | G13: 2027 | H13: 12
A14: Los Mochis | B14: AD | C14: Profesional | D14: Licenciatura en Ingeniería en Logística y Cadena de Suministro | E14: Presencial | F14: SI | G14: 2027 | H14: 18
A15: Querétaro | B15: AD | C15: Profesional | D15: Licenciatura en Contabilidad y Estrategia Financiera | E15: Presencial | F15: SI | G15: 2027 | H15: 12
A16: SLP | B16: AD | C16: Profesional | D16: Licenciatura en Ingeniería en Logística y Cadena de Suministro | E16: Presencial | F16: SI | G16: 2027 | H16: 18
A17: Zapopan | B17: AD | C17: Profesional | D17: Licenciatura en Contabilidad y Estrategia Financiera | E17: Presencial | F17: SI | G17: 2027 | H17: 12
... A60: Chihuahua | B60: AD | C60: Profesional | D60: Ing. en IA | E60: Presencial | F60: SI | G60: 2027 | H60: 18

Sheet cierres_reales
A1: Año | B1: Periodo | C1: Campus | D1: Nivel | E1: NI Real | F1: RI Real | G1: MT Real
A2: 2026 | B2: AD | C2: Aguascalientes | D2: Profesional | E2: 82 | F2: 0 | G2: 82
A3: 2026 | B3: AD | C3: Cancún | D3: Profesional | E3: 104 | F3: 370 | G3: 474
A4: 2026 | B4: AD | C4: Chihuahua | D4: Profesional | E4: 108 | F4: 374 | G4: 482
A5: 2026 | B5: AD | C5: Ciudad Juárez | D5: Profesional | E5: 81 | F5: 383 | G5: 464
A6: 2026 | B6: AD | C6: Cuautitlán Izcalli | D6: Profesional | E6: 269 | F6: 744 | G6: 1013
A7: 2026 | B7: AD | C7: Cuernavaca | D7: Profesional | E7: 95 | F7: 253 | G7: 348
A8: 2026 | B8: AD | C8: Culiacán | D8: Profesional | E8: 251 | F8: 775 | G8: 1026
A9: 2026 | B9: AD | C9: Cumbres | D9: Profesional | E9: 196 | F9: 679 | G9: 875
A10: 2026 | B10: AD | C10: Durango | D10: Profesional | E10: 47 | F10: 125 | G10: 172
A11: 2026 | B11: AD | C11: Ferrería | D11: Profesional | E11: 243 | F11: 885 | G11: 1128
A12: 2026 | B12: AD | C12: Guadalajara | D12: Profesional | E12: 99 | F12: 348 | G12: 447
A13: 2026 | B13: AD | C13: Guadalupe | D13: Profesional | E13: 171 | F13: 684 | G13: 855
... A64: 2026 | B64: AD | C64: Zapopan | D64: Preparatoria | E64: 390 | F64: 683 | G64: 1073

Sheet parametros_pos_ejec
A1: parametro | B1: valor | C1: opciones_validas | D1: como_lo_usara_el_simulador | E1: notas
A2: meta_mt_total_2036 | B2: 43000 | C2: Número | D2: Meta total de MT Posgrado + Ejecutivo en agosto 2036. | E2: Ejemplo: 43000.
A3: anio_meta | B3: 2036 | C3: 2036 | D3: Año de referencia para resolver la meta. | E3: Mantener 2036.
A4: anio_final_simulacion | B4: 2045 | C4: 2045 | D4: La simulación continúa hasta este año. | E4: Aunque la meta principal sea 2036.
A5: anio_base_ni_anual | B5: 2029 | C5: 2029 | D5: Año académico base para tomar el NI anual y crecer hacia adelante. | E5: Debe coincidir con el último año base confiable.
A6: anio_inicio_asincrono | B6: 2028 | C6: 2026-2045 | D6: Antes de este año, NI Asíncrono = 0. | E6: Si empieza en 2028, captura 2028.
A7: anio_deja_captar_sincrono | B7: 2029 | C7: Nunca, 2030-2045 | D7: Desde ese año, NI Síncrono = 0; el RI Síncrono sigue avanzando por matriz. | E7: Default v104: 2029. Puedes cambiarlo en el simulador a Nunca si Síncrono seguirá captando.
A8: reparto_meta_2036_interno | B8: 58% Posgrado / 42% Ejecutivo | C8: Informativo | D8: La v104 lo usa internamente; ya no se captura como control. | E8: Se elimina del UI para evitar confusión.
A9: modo_asincrono_interno | B9: Resolver meta | C9: Informativo | D9: La v104 siempre resuelve cuánto debe aportar Asíncrono para llegar a la meta 2036. | E9: Se elimina del UI.
A10: crecimiento_anual_ni_sincrono_posgrado | B10: 0 | C10: Porcentaje | D10: Crecimiento anual del NI Síncrono de Posgrado si sigue captando. | E10: Si deja de captar, prevalece anio_deja_captar_sincrono.
A11: crecimiento_anual_ni_sincrono_ejecutivo | B11: 0 | C11: Porcentaje | D11: Crecimiento anual del NI Síncrono de Ejecutivo si sigue captando. | E11: Si deja de captar, prevalece anio_deja_captar_sincrono.
A12: crecimiento_anual_ni_asincrono_posgrado_manual | C12: Porcentaje | D12: Solo se usa si modo_asincrono_2036 = Crecimiento manual. | E12: Si modo es Resolver meta, puedes dejarlo vacío.
A13: crecimiento_anual_ni_asincrono_ejecutivo_manual | C13: Porcentaje | D13: Solo se usa si modo_asincrono_2036 = Crecimiento manual. | E13: Si modo es Resolver meta, puedes dejarlo vacío.
A14: usar_stock_ri_agosto_2029 | B14: Sí | C14: Sí, No | D14: Sí: usa stock_ri_agosto_2029 para arrancar la matriz. No: usa MT/RI agregado y estima distribución. | E14: Ideal: Sí si tienes stock por bimestre académico.
A35: parametro | B35: valor | C35: tipo | D35: descripcion | E35: notas
A36: anio_inicio_reparto_ni_sinc_asinc | B36: 2029 | C36: Control | D36: Año académico desde el que el NI total se reparte entre Síncrono y Asíncrono. | E36: Default 2029.
A37: pct_ni_sincrono_posgrado | B37: 0% | C37: Control | D37: Porcentaje del NI anual total de Posgrado que seguirá entrando como Síncrono. | E37: 0% = deja de captar Síncrono; Asíncrono recibe 100%.
A38: pct_ni_sincrono_ejecutivo | B38: 0% | C38: Control | D38: Porcentaje del NI anual total de Ejecutivo que seguirá entrando como Síncrono. | E38: 0% = deja de captar Síncrono; Asíncrono recibe 100%.
A39: crecimiento_anual_ni_total_posgrado | B39: 3% | C39: Control | D39: Crecimiento anual del NI total de Posgrado antes de repartir entre modalidades. | E39: Default v114: 3% anual desde la base de cada periodo 2029.
A40: crecimiento_anual_ni_total_ejecutivo | B40: 3% | C40: Control | D40: Crecimiento anual del NI total de Ejecutivo antes de repartir entre modalidades. | E40: Default v114: 3% anual desde la base de cada periodo 2029.
A41: ri_tetra_inicial_posgrado | B41: 9800 | C41: Control | D41: RI histórico de programas tetra Posgrado que todavía cuenta como Síncrono. | E41: Se agota con egresos_anuales_tetra_posgrado.
A42: egreso_anual_tetra_posgrado | B42: 5000 | C42: Control | D42: Salida anual del RI tetra histórico de Posgrado. | E42: Default 5,000.
A43: ri_tetra_inicial_ejecutivo | B43: 6100 | C43: Control | D43: RI histórico de programas tetra Ejecutivo que todavía cuenta como Síncrono. | E43: Se agota con egresos_anuales_tetra_ejecutivo.
A44: egreso_anual_tetra_ejecutivo | B44: 1200 | C44: Control | D44: Salida anual del RI tetra histórico de Ejecutivo. | E44: Default 1,200.
A47: parametro | B47: valor | C47: tipo | D47: descripcion | E47: notas
A48: anio_meta_pos_ejec | B48: 2036 | C48: Control | D48: Año en que se quiere llegar a la meta MT. | E48: Editable en el simulador.
A49: meta_mt_total | B49: 43000 | C49: Control | D49: Meta MT total Posgrado + Ejecutivo. | E49: Default 43,000.
A50: modo_crecimiento_pos_ejec | B50: Manual por bloques | C50: Resolver meta, Manual por bloques | D50: Define si el simulador calcula el crecimiento requerido o usa bloques manuales por nivel. | E50: Default v125: Resolver meta.
A51: anio_pasar_mt_sincrono_a_asincrono | B51: Nunca | C51: Nunca, 2027-2045 | D51: Año en que se reclasifica la MT Síncrona viva como Asíncrona. | E51: No cambia la MT total; cambia la modalidad.
A60: pmp_mt_pos_ejec | B60: Hoja editable | C60: Insumo | D60: Captura MT PMP oficial hasta 2029. | E60: El simulador usa esa MT hasta 2029; desde Enero 2030 proyecta con crecimientos.
A61: inicio_crecimiento_proyectado | B61: Enero 2030 | C61: Regla | D61: Inicio de crecimiento manual o resuelto. | E61: Las capturas PMP cubren hasta 2029.

Sheet ni_bimestral_pos_ejec
A1: anio_academico | B1: periodo | C1: anio_calendario | D1: nivel | E1: modalidad | F1: NI
A2: 2026 | B2: Agosto | C2: 2026 | D2: Posgrado | E2: Síncrono | F2: 1866
A3: 2026 | B3: Octubre | C3: 2026 | D3: Posgrado | E3: Síncrono | F3: 1660
A4: 2026 | B4: Enero | C4: 2027 | D4: Posgrado | E4: Síncrono | F4: 2062
A5: 2026 | B5: Marzo | C5: 2027 | D5: Posgrado | E5: Síncrono | F5: 1513
A6: 2026 | B6: Junio | C6: 2027 | D6: Posgrado | E6: Síncrono | F6: 2245
A7: 2026 | B7: Agosto | C7: 2026 | D7: Posgrado | E7: Asíncrono | F7: 0
A8: 2026 | B8: Octubre | C8: 2026 | D8: Posgrado | E8: Asíncrono | F8: 0
A9: 2026 | B9: Enero | C9: 2027 | D9: Posgrado | E9: Asíncrono | F9: 0
A10: 2026 | B10: Marzo | C10: 2027 | D10: Posgrado | E10: Asíncrono | F10: 0
A11: 2026 | B11: Junio | C11: 2027 | D11: Posgrado | E11: Asíncrono | F11: 0
A12: 2026 | B12: Agosto | C12: 2026 | D12: Ejecutivo | E12: Síncrono | F12: 952
A13: 2026 | B13: Octubre | C13: 2026 | D13: Ejecutivo | E13: Síncrono | F13: 867
... A86: 2025 | B86: Junio | C86: 2026 | D86: Ejecutivo | E86: Síncrono | F86: 785

Sheet crecimiento_anual_pos_ejec
A1: anio_academico | B1: nivel | C1: modalidad | D1: crecimiento_ni_anual | E1: captacion_activa | F1: modo_uso | G1: notas
A2: 2030 | B2: Posgrado | C2: Síncrono | D2: 0.03 | E2: Sí | F2: Síncrono | G2: Se usa si Síncrono sigue captando. Si anio_deja_captar_sincrono aplica, NI Síncrono será 0 desde ese año.
A3: 2030 | B3: Posgrado | C3: Asíncrono | E3: Sí | F3: Asíncrono manual | G3: Solo se usa si modo_asincrono_2036 = Crecimiento manual. Si es Resolver meta, puede quedar vacío.
A4: 2030 | B4: Ejecutivo | C4: Síncrono | D4: 0.03 | E4: Sí | F4: Síncrono | G4: Se usa si Síncrono sigue captando. Si anio_deja_captar_sincrono aplica, NI Síncrono será 0 desde ese año.
A5: 2030 | B5: Ejecutivo | C5: Asíncrono | E5: Sí | F5: Asíncrono manual | G5: Solo se usa si modo_asincrono_2036 = Crecimiento manual. Si es Resolver meta, puede quedar vacío.
A6: 2031 | B6: Posgrado | C6: Síncrono | D6: 0.03 | E6: Sí | F6: Síncrono | G6: Se usa si Síncrono sigue captando. Si anio_deja_captar_sincrono aplica, NI Síncrono será 0 desde ese año.
A7: 2031 | B7: Posgrado | C7: Asíncrono | E7: Sí | F7: Asíncrono manual | G7: Solo se usa si modo_asincrono_2036 = Crecimiento manual. Si es Resolver meta, puede quedar vacío.
A8: 2031 | B8: Ejecutivo | C8: Síncrono | D8: 0.03 | E8: Sí | F8: Síncrono | G8: Se usa si Síncrono sigue captando. Si anio_deja_captar_sincrono aplica, NI Síncrono será 0 desde ese año.
A9: 2031 | B9: Ejecutivo | C9: Asíncrono | E9: Sí | F9: Asíncrono manual | G9: Solo se usa si modo_asincrono_2036 = Crecimiento manual. Si es Resolver meta, puede quedar vacío.
A10: 2032 | B10: Posgrado | C10: Síncrono | D10: 0.03 | E10: Sí | F10: Síncrono | G10: Se usa si Síncrono sigue captando. Si anio_deja_captar_sincrono aplica, NI Síncrono será 0 desde ese año.
A11: 2032 | B11: Posgrado | C11: Asíncrono | E11: Sí | F11: Asíncrono manual | G11: Solo se usa si modo_asincrono_2036 = Crecimiento manual. Si es Resolver meta, puede quedar vacío.
A12: 2032 | B12: Ejecutivo | C12: Síncrono | D12: 0.03 | E12: Sí | F12: Síncrono | G12: Se usa si Síncrono sigue captando. Si anio_deja_captar_sincrono aplica, NI Síncrono será 0 desde ese año.
A13: 2032 | B13: Ejecutivo | C13: Asíncrono | E13: Sí | F13: Asíncrono manual | G13: Solo se usa si modo_asincrono_2036 = Crecimiento manual. Si es Resolver meta, puede quedar vacío.
A14: 2033 | B14: Posgrado | C14: Síncrono | D14: 0.03 | E14: Sí | F14: Síncrono | G14: Se usa si Síncrono sigue captando. Si anio_deja_captar_sincrono aplica, NI Síncrono será 0 desde ese año.
A15: 2033 | B15: Posgrado | C15: Asíncrono | E15: Sí | F15: Asíncrono manual | G15: Solo se usa si modo_asincrono_2036 = Crecimiento manual. Si es Resolver meta, puede quedar vacío.
A16: 2033 | B16: Ejecutivo | C16: Síncrono | D16: 0.03 | E16: Sí | F16: Síncrono | G16: Se usa si Síncrono sigue captando. Si anio_deja_captar_sincrono aplica, NI Síncrono será 0 desde ese año.
A17: 2033 | B17: Ejecutivo | C17: Asíncrono | E17: Sí | F17: Asíncrono manual | G17: Solo se usa si modo_asincrono_2036 = Crecimiento manual. Si es Resolver meta, puede quedar vacío.
A18: 2034 | B18: Posgrado | C18: Síncrono | D18: 0.03 | E18: Sí | F18: Síncrono | G18: Se usa si Síncrono sigue captando. Si anio_deja_captar_sincrono aplica, NI Síncrono será 0 desde ese año.
A19: 2034 | B19: Posgrado | C19: Asíncrono | E19: Sí | F19: Asíncrono manual | G19: Solo se usa si modo_asincrono_2036 = Crecimiento manual. Si es Resolver meta, puede quedar vacío.
A20: 2034 | B20: Ejecutivo | C20: Síncrono | D20: 0.03 | E20: Sí | F20: Síncrono | G20: Se usa si Síncrono sigue captando. Si anio_deja_captar_sincrono aplica, NI Síncrono será 0 desde ese año.
A21: 2034 | B21: Ejecutivo | C21: Asíncrono | E21: Sí | F21: Asíncrono manual | G21: Solo se usa si modo_asincrono_2036 = Crecimiento manual. Si es Resolver meta, puede quedar vacío.
A22: 2035 | B22: Posgrado | C22: Síncrono | D22: 0.03 | E22: Sí | F22: Síncrono | G22: Se usa si Síncrono sigue captando. Si anio_deja_captar_sincrono aplica, NI Síncrono será 0 desde ese año.
A23: 2035 | B23: Posgrado | C23: Asíncrono | E23: Sí | F23: Asíncrono manual | G23: Solo se usa si modo_asincrono_2036 = Crecimiento manual. Si es Resolver meta, puede quedar vacío.
A24: 2035 | B24: Ejecutivo | C24: Síncrono | D24: 0.03 | E24: Sí | F24: Síncrono | G24: Se usa si Síncrono sigue captando. Si anio_deja_captar_sincrono aplica, NI Síncrono será 0 desde ese año.
A25: 2035 | B25: Ejecutivo | C25: Asíncrono | E25: Sí | F25: Asíncrono manual | G25: Solo se usa si modo_asincrono_2036 = Crecimiento manual. Si es Resolver meta, puede quedar vacío.
A26: 2036 | B26: Posgrado | C26: Síncrono | D26: 0.03 | E26: Sí | F26: Síncrono | G26: Se usa si Síncrono sigue captando. Si anio_deja_captar_sincrono aplica, NI Síncrono será 0 desde ese año.
A27: 2036 | B27: Posgrado | C27: Asíncrono | E27: Sí | F27: Asíncrono manual | G27: Solo se usa si modo_asincrono_2036 = Crecimiento manual. Si es Resolver meta, puede quedar vacío.
A28: 2036 | B28: Ejecutivo | C28: Síncrono | D28: 0.03 | E28: Sí | F28: Síncrono | G28: Se usa si Síncrono sigue captando. Si anio_deja_captar_sincrono aplica, NI Síncrono será 0 desde ese año.
A29: 2036 | B29: Ejecutivo | C29: Asíncrono | E29: Sí | F29: Asíncrono manual | G29: Solo se usa si modo_asincrono_2036 = Crecimiento manual. Si es Resolver meta, puede quedar vacío.
A30: 2037 | B30: Posgrado | C30: Síncrono | D30: 0.03 | E30: Sí | F30: Síncrono | G30: Se usa si Síncrono sigue captando. Si anio_deja_captar_sincrono aplica, NI Síncrono será 0 desde ese año.
A31: 2037 | B31: Posgrado | C31: Asíncrono | E31: Sí | F31: Asíncrono manual | G31: Solo se usa si modo_asincrono_2036 = Crecimiento manual. Si es Resolver meta, puede quedar vacío.
A32: 2037 | B32: Ejecutivo | C32: Síncrono | D32: 0.03 | E32: Sí | F32: Síncrono | G32: Se usa si Síncrono sigue captando. Si anio_deja_captar_sincrono aplica, NI Síncrono será 0 desde ese año.
A33: 2037 | B33: Ejecutivo | C33: Asíncrono | E33: Sí | F33: Asíncrono manual | G33: Solo se usa si modo_asincrono_2036 = Crecimiento manual. Si es Resolver meta, puede quedar vacío.
A34: 2038 | B34: Posgrado | C34: Síncrono | D34: 0.03 | E34: Sí | F34: Síncrono | G34: Se usa si Síncrono sigue captando. Si anio_deja_captar_sincrono aplica, NI Síncrono será 0 desde ese año.
A35: 2038 | B35: Posgrado | C35: Asíncrono | E35: Sí | F35: Asíncrono manual | G35: Solo se usa si modo_asincrono_2036 = Crecimiento manual. Si es Resolver meta, puede quedar vacío.
A36: 2038 | B36: Ejecutivo | C36: Síncrono | D36: 0.03 | E36: Sí | F36: Síncrono | G36: Se usa si Síncrono sigue captando. Si anio_deja_captar_sincrono aplica, NI Síncrono será 0 desde ese año.
A37: 2038 | B37: Ejecutivo | C37: Asíncrono | E37: Sí | F37: Asíncrono manual | G37: Solo se usa si modo_asincrono_2036 = Crecimiento manual. Si es Resolver meta, puede quedar vacío.
A38: 2039 | B38: Posgrado | C38: Síncrono | D38: 0.03 | E38: Sí | F38: Síncrono | G38: Se usa si Síncrono sigue captando. Si anio_deja_captar_sincrono aplica, NI Síncrono será 0 desde ese año.
A39: 2039 | B39: Posgrado | C39: Asíncrono | E39: Sí | F39: Asíncrono manual | G39: Solo se usa si modo_asincrono_2036 = Crecimiento manual. Si es Resolver meta, puede quedar vacío.
A40: 2039 | B40: Ejecutivo | C40: Síncrono | D40: 0.03 | E40: Sí | F40: Síncrono | G40: Se usa si Síncrono sigue captando. Si anio_deja_captar_sincrono aplica, NI Síncrono será 0 desde ese año.
...

Sheet reparto_periodos_pos_ejec
A1: nivel | B1: modalidad | C1: periodo | D1: pct_reparto | E1: notas
A2: Posgrado | B2: Síncrono | C2: Agosto | D2: 18.5 | E2: Captura porcentaje del NI anual. La suma de los 5 periodos por Nivel + Modalidad debe ser 100%.
A3: Posgrado | B3: Síncrono | C3: Octubre | D3: 18.5 | E3: Captura porcentaje del NI anual. La suma de los 5 periodos por Nivel + Modalidad debe ser 100%.
A4: Posgrado | B4: Síncrono | C4: Enero | D4: 22 | E4: Captura porcentaje del NI anual. La suma de los 5 periodos por Nivel + Modalidad debe ser 100%.
A5: Posgrado | B5: Síncrono | C5: Marzo | D5: 16 | E5: Captura porcentaje del NI anual. La suma de los 5 periodos por Nivel + Modalidad debe ser 100%.
A6: Posgrado | B6: Síncrono | C6: Junio | D6: 25 | E6: Captura porcentaje del NI anual. La suma de los 5 periodos por Nivel + Modalidad debe ser 100%.
A7: Posgrado | B7: Asíncrono | C7: Agosto | D7: 18.5 | E7: Captura porcentaje del NI anual. La suma de los 5 periodos por Nivel + Modalidad debe ser 100%.
A8: Posgrado | B8: Asíncrono | C8: Octubre | D8: 18.5 | E8: Captura porcentaje del NI anual. La suma de los 5 periodos por Nivel + Modalidad debe ser 100%.
A9: Posgrado | B9: Asíncrono | C9: Enero | D9: 22 | E9: Captura porcentaje del NI anual. La suma de los 5 periodos por Nivel + Modalidad debe ser 100%.
A10: Posgrado | B10: Asíncrono | C10: Marzo | D10: 16 | E10: Captura porcentaje del NI anual. La suma de los 5 periodos por Nivel + Modalidad debe ser 100%.
A11: Posgrado | B11: Asíncrono | C11: Junio | D11: 25 | E11: Captura porcentaje del NI anual. La suma de los 5 periodos por Nivel + Modalidad debe ser 100%.
A12: Ejecutivo | B12: Síncrono | C12: Agosto | D12: 20.5 | E12: Captura porcentaje del NI anual. La suma de los 5 periodos por Nivel + Modalidad debe ser 100%.
A13: Ejecutivo | B13: Síncrono | C13: Octubre | D13: 19 | E13: Captura porcentaje del NI anual. La suma de los 5 periodos por Nivel + Modalidad debe ser 100%.
... A21: Ejecutivo | B21: Asíncrono | C21: Junio | D21: 21.5 | E21: Captura porcentaje del NI anual. La suma de los 5 periodos por Nivel + Modalidad debe ser 100%.

Sheet tasas_ri_bimestre_pos_ejec
A1: nivel | B1: modalidad | C1: bimestre_origen | D1: bimestre_destino | E1: tasa | F1: notas
A2: Posgrado | B2: Síncrono | C2: B1 | D2: B2 | E2: 0.9 | F2: Posgrado: duración normal aprox. 10 bimestres; se dejan 15 tasas para rezago/extensión.
A3: Posgrado | B3: Síncrono | C3: B2 | D3: B3 | E3: 0.95 | F3: Posgrado: duración normal aprox. 10 bimestres; se dejan 15 tasas para rezago/extensión.
A4: Posgrado | B4: Síncrono | C4: B3 | D4: B4 | E4: 0.95 | F4: Posgrado: duración normal aprox. 10 bimestres; se dejan 15 tasas para rezago/extensión.
